<robot name="car">
    
    <!-- base_link ////////////////////////////////////////////////////////////////-->
    <link name="base_link">
        <!-- <inertial>
            <origin xyz="0.0 0.0 0.0" rpy="0.0 0.0 0.0"/>
            <mass value="0.0"/>
            <inertia ixx="0.0" ixy="0.0" ixz="0.0" iyy="0.0" iyz="0.0" izz="0.0"/>
        </inertial> -->
        <visual>
            <origin xyz="0.0 0.0 0.0" rpy="0.0 0.0 0.0"/>
            <geometry>
                <sphere radius="0.0001"/>
            </geometry>
            <material name="base_link">
                <color rgba="1.0 0.0 0.0 1.0"/>
                <!-- <texture filename=""/> -->
            </material>
        </visual>
        <!-- <collision>
            <origin xyz="0.0 0.0 0.0" rpy="0.0 0.0 0.0"/>
            <geometry>
                <sphere radius="0.0"/>
            </geometry>
        </collision> -->
    </link>

    <!-- car ////////////////////////////////////////////////////////////////////// -->
    <link name="car">
        <!-- <inertial>
            <origin xyz="0.0 0.0 0.0" rpy="0.0 0.0 0.0"/>
            <mass value="0.0"/>
            <inertia ixx="0.0" ixy="0.0" ixz="0.0" iyy="0.0" iyz="0.0" izz="0.0"/>
        </inertial> -->
        <visual>
            <origin xyz="0.0 0.0 0.0" rpy="0.0 0.0 0.0"/>
            <geometry>
                <cylinder radius="0.1" length="0.08"/>
            </geometry>
            <material name="car">
                <color rgba="1.0 0.0 0.0 0.5"/>
                <!-- <texture filename=""/> -->
            </material>
        </visual>
        <!-- <collision>
            <origin xyz="0.0 0.0 0.0" rpy="0.0 0.0 0.0"/>
            <geometry>
                <cylinder radius="0.0" length="0.0"/>
            </geometry>
        </collision> -->
    </link>

    <joint name="car2base_link" type="fixed">
        <origin xyz="0.0 0.0 0.055" rpy="0.0 0.0 0.0"/>
        <parent link="base_link"/>
        <child link="car"/>
        <!-- <axis xyz="0.0 0.0 0.0"/> -->
        <!-- <limit lower="0.0" upper="0.0" effort="0.0" velocity="0.0"/> -->
    </joint>

    <!-- wheels /////////////////////////////////////////////////////////////////// -->
    <link name="left_wheel">
        <!-- <inertial>
            <origin xyz="0.0 0.0 0.0" rpy="0.0 0.0 0.0"/>
            <mass value="0.0"/>
            <inertia ixx="0.0" ixy="0.0" ixz="0.0" iyy="0.0" iyz="0.0" izz="0.0"/>
        </inertial> -->
        <visual>
            <origin xyz="0.0 0.0 0.0" rpy="1.5708 0.0 0.0"/>
            <geometry>
                <cylinder radius="0.0325" length="0.015"/>
            </geometry>
            <material name="left_wheel">
                <color rgba="0.0 0.0 0.0 1.0"/>
                <!-- <texture filename=""/> -->
            </material>
        </visual>
        <!-- <collision>
            <origin xyz="0.0 0.0 0.0" rpy="0.0 0.0 0.0"/>
            <geometry>
                <cylinder radius="0.0" length="0.0"/>
            </geometry>
        </collision> -->
    </link>

    <joint name="left_wheel2car" type="continuous">
        <origin xyz="0.0 0.1075 -0.0225" rpy="0.0 0.0 0.0"/>
        <parent link="car"/>
        <child link="left_wheel"/>
        <axis xyz="0.0 1.0 0.0"/>
        <!-- <limit lower="0.0" upper="0.0" effort="0.0" velocity="0.0"/> -->
    </joint>

    <link name="right_wheel">
        <!-- <inertial>
            <origin xyz="0.0 0.0 0.0" rpy="0.0 0.0 0.0"/>
            <mass value="0.0"/>
            <inertia ixx="0.0" ixy="0.0" ixz="0.0" iyy="0.0" iyz="0.0" izz="0.0"/>
        </inertial> -->
        <visual>
            <origin xyz="0.0 0.0 0.0" rpy="1.5708 0.0 0.0"/>
            <geometry>
                <cylinder radius="0.0325" length="0.015"/>
            </geometry>
            <material name="right_wheel">
                <color rgba="0.0 0.0 0.0 1.0"/>
                <!-- <texture filename=""/> -->
            </material>
        </visual>
        <!-- <collision>
            <origin xyz="0.0 0.0 0.0" rpy="0.0 0.0 0.0"/>
            <geometry>
                <cylinder radius="0.0" length="0.0"/>
            </geometry>
        </collision> -->
    </link>

    <joint name="right_wheel2car" type="continuous">
        <origin xyz="0.0 -0.1075 -0.0225" rpy="0.0 0.0 0.0"/>
        <parent link="car"/>
        <child link="right_wheel"/>
        <axis xyz="0.0 1.0 0.0"/>
        <!-- <limit lower="0.0" upper="0.0" effort="0.0" velocity="0.0"/> -->
    </joint>

    <link name="front_wheel">
        <!-- <inertial>
            <origin xyz="0.0 0.0 0.0" rpy="0.0 0.0 0.0"/>
            <mass value="0.0"/>
            <inertia ixx="0.0" ixy="0.0" ixz="0.0" iyy="0.0" iyz="0.0" izz="0.0"/>
        </inertial> -->
        <visual>
            <origin xyz="0.0 0.0 0.0" rpy="0.0 0.0 0.0"/>
            <geometry>
                <sphere radius="0.0075"/>
            </geometry>
            <material name="front_wheel">
                <color rgba="0.0 0.0 0.0 1.0"/>
                <!-- <texture filename=""/> -->
            </material>
        </visual>
        <!-- <collision>
            <origin xyz="0.0 0.0 0.0" rpy="0.0 0.0 0.0"/>
            <geometry>
                <sphere radius="0.0"/>
            </geometry>
        </collision> -->
    </link>

    <joint name="front_wheel2car" type="continuous">
        <origin xyz="0.08 0.0 -0.0475" rpy="0.0 0.0 0.0"/>
        <parent link="car"/>
        <child link="front_wheel"/>
        <axis xyz="0.0 1.0 0.0"/>
        <!-- <limit lower="0.0" upper="0.0" effort="0.0" velocity="0.0"/> -->
    </joint>

    <link name="back_wheel">
        <!-- <inertial>
            <origin xyz="0.0 0.0 0.0" rpy="0.0 0.0 0.0"/>
            <mass value="0.0"/>
            <inertia ixx="0.0" ixy="0.0" ixz="0.0" iyy="0.0" iyz="0.0" izz="0.0"/>
        </inertial> -->
        <visual>
            <origin xyz="0.0 0.0 0.0" rpy="0.0 0.0 0.0"/>
            <geometry>
                <sphere radius="0.0075"/>
            </geometry>
            <material name="back_wheel">
                <color rgba="0.0 0.0 0.0 1.0"/>
                <!-- <texture filename=""/> -->
            </material>
        </visual>
        <!-- <collision>
            <origin xyz="0.0 0.0 0.0" rpy="0.0 0.0 0.0"/>
            <geometry>
                <sphere radius="0.0"/>
            </geometry>
        </collision> -->
    </link>

    <joint name="back_wheel2car" type="continuous">
        <origin xyz="-0.08 0.0 -0.0475" rpy="0.0 0.0 0.0"/>
        <parent link="car"/>
        <child link="back_wheel"/>
        <axis xyz="0.0 1.0 0.0"/>
        <!-- <limit lower="0.0" upper="0.0" effort="0.0" velocity="0.0"/> -->
    </joint>

</robot>